Workbook

Sheet サマリ
A1: 年間工数管理サマリ
A2: 対象年 | B2: 2026 | C2: ← クリーム色のセルが入力箇所です
A3: =IF(サマリ!$B$2<>YEAR(TODAY()),"※対象年が本日と異なります",HYPERLINK("#'"&TEXT(TODAY(),"mm")&"月'!A4","▶ 当月（"&TEXT(TODAY(),"m")&"月度）の明細シートを開く")) -> ▶ 当月（8月度）の明細シートを開く
A5: ① 月別工数サマリ
A6: 月 | B6: 実績工数 | C6: 前月差 | D6: 前月比 | E6: 累計
A7: 1月 | B7: =SUM('01月'!$F$4:$F$503) -> 3.5 | C7: - | D7: - | E7: =B7 -> 3.5
A8: 2月 | B8: =SUM('02月'!$F$4:$F$503) -> 0 | C8: =B8-B7 -> -3.5 | D8: =IF(B7=0,"",B8/B7-1) -> -1 | E8: =E7+B8 -> 3.5
A9: 3月 | B9: =SUM('03月'!$F$4:$F$503) -> 0 | C9: =B9-B8 -> 0 | D9: =IF(B8=0,"",B9/B8-1) | E9: =E8+B9 -> 3.5
A10: 4月 | B10: =SUM('04月'!$F$4:$F$503) -> 0 | C10: =B10-B9 -> 0 | D10: =IF(B9=0,"",B10/B9-1) | E10: =E9+B10 -> 3.5
A11: 5月 | B11: =SUM('05月'!$F$4:$F$503) -> 0 | C11: =B11-B10 -> 0 | D11: =IF(B10=0,"",B11/B10-1) | E11: =E10+B11 -> 3.5
A12: 6月 | B12: =SUM('06月'!$F$4:$F$503) -> 0 | C12: =B12-B11 -> 0 | D12: =IF(B11=0,"",B12/B11-1) | E12: =E11+B12 -> 3.5
A13: 7月 | B13: =SUM('07月'!$F$4:$F$503) -> 0 | C13: =B13-B12 -> 0 | D13: =IF(B12=0,"",B13/B12-1) | E13: =E12+B13 -> 3.5
A14: 8月 | B14: =SUM('08月'!$F$4:$F$503) -> 0 | C14: =B14-B13 -> 0 | D14: =IF(B13=0,"",B14/B13-1) | E14: =E13+B14 -> 3.5
A15: 9月 | B15: =SUM('09月'!$F$4:$F$503) -> 0 | C15: =B15-B14 -> 0 | D15: =IF(B14=0,"",B15/B14-1) | E15: =E14+B15 -> 3.5
A16: 10月 | B16: =SUM('10月'!$F$4:$F$503) -> 0 | C16: =B16-B15 -> 0 | D16: =IF(B15=0,"",B16/B15-1) | E16: =E15+B16 -> 3.5
A17: 11月 | B17: =SUM('11月'!$F$4:$F$503) -> 0 | C17: =B17-B16 -> 0 | D17: =IF(B16=0,"",B17/B16-1) | E17: =E16+B17 -> 3.5
A18: 12月 | B18: =SUM('12月'!$F$4:$F$503) -> 0 | C18: =B18-B17 -> 0 | D18: =IF(B17=0,"",B18/B17-1) | E18: =E17+B18 -> 3.5
A19: 年間合計 | B19: =SUM(B7:B18) -> 3.5
A21: ② 内訳別の集計
A22: =HYPERLINK("#'集計_行程'!A4","▶ 集計_行程") -> ▶ 集計_行程 | B22: 行程別（一次保守／改修／事業運用改善 など）
A23: =HYPERLINK("#'集計_タスク1'!A4","▶ 集計_タスク1") -> ▶ 集計_タスク1 | B23: タスク1別（問い合わせ対応／アプリ領域／基盤領域 など）
A24: =HYPERLINK("#'集計_タスク2'!A4","▶ 集計_タスク2") -> ▶ 集計_タスク2 | B24: タスク2別（●●社問い合わせ対応／MTG／実作業 など）
A25: =HYPERLINK("#'集計_担当者'!A4","▶ 集計_担当者") -> ▶ 集計_担当者 | B25: 担当者別
A26: ※各集計シートの項目は工数明細から自動取得されます（マスタ管理は不要です）。

Sheet 集計_行程
A1: 行程別 月次工数
A2: ※水色セルに「数式」シートの数式を貼り付けてください（貼り付け後、水色の塗りつぶしは消して構いません）。項目は明細から自動取得され、行数も自動で伸縮します。
A3: 合計 | B3: {=SUMIFS(統合データ!$F$2:$F$6001,統合データ!$A$2:$A$6001,B4:M4)} -> 3.5 | C3: 0 | D3: 0 | E3: 0 | F3: 0 | G3: 0 | H3: 0 | I3: 0 | J3: 0 | K3: 0 | L3: 0 | M3: 0 | N3: =SUM(統合データ!$F$2:$F$6001) -> 3.5
A4: 行程 | B4: 1 | C4: 2 | D4: 3 | E4: 4 | F4: 5 | G4: 6 | H4: 7 | I4: 8 | J4: 9 | K4: 10 | L4: 11 | M4: 12 | N4: 合計 | O4: 構成比
A5: {=_xlfn._xlws.SORT(_xlfn.UNIQUE(_xlfn._xlws.FILTER(統合データ!$B$2:$B$6001,統合データ!$B$2:$B$6001<>"")))} -> 一次保守 | B5: {=SUMIFS(統合データ!$F$2:$F$6001,統合データ!$B$2:$B$6001,_xlfn.ANCHORARRAY($A5),統合データ!$A$2:$A$6001,B$4:M$4)} -> 3.5 | C5: 0 | D5: 0 | E5: 0 | F5: 0 | G5: 0 | H5: 0 | I5: 0 | J5: 0 | K5: 0 | L5: 0 | M5: 0 | N5: {=SUMIFS(統合データ!$F$2:$F$6001,統合データ!$B$2:$B$6001,_xlfn.ANCHORARRAY($A5))} -> 3.5 | O5: {=IFERROR(_xlfn.ANCHORARRAY(N5)/$N$3,"")} -> 1

Sheet 集計_タスク1
A1: タスク1別 月次工数
A2: ※水色セルに「数式」シートの数式を貼り付けてください（貼り付け後、水色の塗りつぶしは消して構いません）。項目は明細から自動取得され、行数も自動で伸縮します。
A3: 合計 | B3: {=SUMIFS(統合データ!$F$2:$F$6001,統合データ!$A$2:$A$6001,B4:M4)} -> 3.5 | C3: 0 | D3: 0 | E3: 0 | F3: 0 | G3: 0 | H3: 0 | I3: 0 | J3: 0 | K3: 0 | L3: 0 | M3: 0 | N3: =SUM(統合データ!$F$2:$F$6001) -> 3.5
A4: タスク1 | B4: 1 | C4: 2 | D4: 3 | E4: 4 | F4: 5 | G4: 6 | H4: 7 | I4: 8 | J4: 9 | K4: 10 | L4: 11 | M4: 12 | N4: 合計 | O4: 構成比
A5: {=_xlfn._xlws.SORT(_xlfn.UNIQUE(_xlfn._xlws.FILTER(統合データ!$C$2:$C$6001,統合データ!$C$2:$C$6001<>"")))} -> 問い合わせ対応 | B5: {=SUMIFS(統合データ!$F$2:$F$6001,統合データ!$C$2:$C$6001,_xlfn.ANCHORARRAY($A5),統合データ!$A$2:$A$6001,B$4:M$4)} -> 3.5 | C5: 0 | D5: 0 | E5: 0 | F5: 0 | G5: 0 | H5: 0 | I5: 0 | J5: 0 | K5: 0 | L5: 0 | M5: 0 | N5: {=SUMIFS(統合データ!$F$2:$F$6001,統合データ!$C$2:$C$6001,_xlfn.ANCHORARRAY($A5))} -> 3.5 | O5: {=IFERROR(_xlfn.ANCHORARRAY(N5)/$N$3,"")} -> 1

Sheet 集計_タスク2
A1: タスク2別 月次工数
A2: ※水色セルに「数式」シートの数式を貼り付けてください（貼り付け後、水色の塗りつぶしは消して構いません）。項目は明細から自動取得され、行数も自動で伸縮します。
A3: 合計 | B3: {=SUMIFS(統合データ!$F$2:$F$6001,統合データ!$A$2:$A$6001,B4:M4)} -> 3.5 | C3: 0 | D3: 0 | E3: 0 | F3: 0 | G3: 0 | H3: 0 | I3: 0 | J3: 0 | K3: 0 | L3: 0 | M3: 0 | N3: =SUM(統合データ!$F$2:$F$6001) -> 3.5
A4: タスク2 | B4: 1 | C4: 2 | D4: 3 | E4: 4 | F4: 5 | G4: 6 | H4: 7 | I4: 8 | J4: 9 | K4: 10 | L4: 11 | M4: 12 | N4: 合計 | O4: 構成比
A5: {=_xlfn._xlws.SORT(_xlfn.UNIQUE(_xlfn._xlws.FILTER(統合データ!$D$2:$D$6001,統合データ!$D$2:$D$6001<>"")))} -> ●●社問い合わせ対応 | B5: {=SUMIFS(統合データ!$F$2:$F$6001,統合データ!$D$2:$D$6001,_xlfn.ANCHORARRAY($A5),統合データ!$A$2:$A$6001,B$4:M$4)} -> 3.5 | C5: 0 | D5: 0 | E5: 0 | F5: 0 | G5: 0 | H5: 0 | I5: 0 | J5: 0 | K5: 0 | L5: 0 | M5: 0 | N5: {=SUMIFS(統合データ!$F$2:$F$6001,統合データ!$D$2:$D$6001,_xlfn.ANCHORARRAY($A5))} -> 3.5 | O5: {=IFERROR(_xlfn.ANCHORARRAY(N5)/$N$3,"")} -> 1

Sheet 集計_担当者
A1: 担当者別 月次工数
A2: ※水色セルに「数式」シートの数式を貼り付けてください（貼り付け後、水色の塗りつぶしは消して構いません）。項目は明細から自動取得され、行数も自動で伸縮します。
A3: 合計 | B3: {=SUMIFS(統合データ!$F$2:$F$6001,統合データ!$A$2:$A$6001,B4:M4)} -> 3.5 | C3: 0 | D3: 0 | E3: 0 | F3: 0 | G3: 0 | H3: 0 | I3: 0 | J3: 0 | K3: 0 | L3: 0 | M3: 0 | N3: =SUM(統合データ!$F$2:$F$6001) -> 3.5
A4: 担当者 | B4: 1 | C4: 2 | D4: 3 | E4: 4 | F4: 5 | G4: 6 | H4: 7 | I4: 8 | J4: 9 | K4: 10 | L4: 11 | M4: 12 | N4: 合計 | O4: 構成比
A5: {=_xlfn._xlws.SORT(_xlfn.UNIQUE(_xlfn._xlws.FILTER(統合データ!$E$2:$E$6001,統合データ!$E$2:$E$6001<>"")))} -> 山田 | B5: {=SUMIFS(統合データ!$F$2:$F$6001,統合データ!$E$2:$E$6001,_xlfn.ANCHORARRAY($A5),統合データ!$A$2:$A$6001,B$4:M$4)} -> 3.5 | C5: 0 | D5: 0 | E5: 0 | F5: 0 | G5: 0 | H5: 0 | I5: 0 | J5: 0 | K5: 0 | L5: 0 | M5: 0 | N5: {=SUMIFS(統合データ!$F$2:$F$6001,統合データ!$E$2:$E$6001,_xlfn.ANCHORARRAY($A5))} -> 3.5 | O5: {=IFERROR(_xlfn.ANCHORARRAY(N5)/$N$3,"")} -> 1

Sheet 01月
A1: 1月度 工数明細 | C1: =IF(AND(サマリ!$B$2=YEAR(TODAY()),MONTH(TODAY())=1),"★ 当月","") | E1: 月合計 | F1: =SUM(F4:F503) -> 3.5
A2: ※4行目〜503行目に明細を貼り付けてください（合計行はその下）。日付はYYYYMM形式（例：202601）。
A3: 日付 | B3: 行程 | C3: タスク1 | D3: タスク2 | E3: タスク3 | F3: 工数 | G3: 担当者 | H3: 備考
A4: 202601 | B4: 一次保守 | C4: 問い合わせ対応 | D4: ●●社問い合わせ対応 | E4: 自社内 | F4: 3.5 | G4: 山田 | H4: ※記入例。上書きして使ってください
E505: 合計 | F505: =SUM(F4:F503) -> 3.5

Sheet 02月
A1: 2月度 工数明細 | C1: =IF(AND(サマリ!$B$2=YEAR(TODAY()),MONTH(TODAY())=2),"★ 当月","") | E1: 月合計 | F1: =SUM(F4:F503) -> 0
A2: ※4行目〜503行目に明細を貼り付けてください（合計行はその下）。日付はYYYYMM形式（例：202601）。
A3: 日付 | B3: 行程 | C3: タスク1 | D3: タスク2 | E3: タスク3 | F3: 工数 | G3: 担当者 | H3: 備考
E505: 合計 | F505: =SUM(F4:F503) -> 0

Sheet 03月
A1: 3月度 工数明細 | C1: =IF(AND(サマリ!$B$2=YEAR(TODAY()),MONTH(TODAY())=3),"★ 当月","") | E1: 月合計 | F1: =SUM(F4:F503) -> 0
A2: ※4行目〜503行目に明細を貼り付けてください（合計行はその下）。日付はYYYYMM形式（例：202601）。
A3: 日付 | B3: 行程 | C3: タスク1 | D3: タスク2 | E3: タスク3 | F3: 工数 | G3: 担当者 | H3: 備考
E505: 合計 | F505: =SUM(F4:F503) -> 0

Sheet 04月
A1: 4月度 工数明細 | C1: =IF(AND(サマリ!$B$2=YEAR(TODAY()),MONTH(TODAY())=4),"★ 当月","") | E1: 月合計 | F1: =SUM(F4:F503) -> 0
A2: ※4行目〜503行目に明細を貼り付けてください（合計行はその下）。日付はYYYYMM形式（例：202601）。
A3: 日付 | B3: 行程 | C3: タスク1 | D3: タスク2 | E3: タスク3 | F3: 工数 | G3: 担当者 | H3: 備考
E505: 合計 | F505: =SUM(F4:F503) -> 0

Sheet 05月
A1: 5月度 工数明細 | C1: =IF(AND(サマリ!$B$2=YEAR(TODAY()),MONTH(TODAY())=5),"★ 当月","") | E1: 月合計 | F1: =SUM(F4:F503) -> 0
A2: ※4行目〜503行目に明細を貼り付けてください（合計行はその下）。日付はYYYYMM形式（例：202601）。
A3: 日付 | B3: 行程 | C3: タスク1 | D3: タスク2 | E3: タスク3 | F3: 工数 | G3: 担当者 | H3: 備考
E505: 合計 | F505: =SUM(F4:F503) -> 0

Sheet 06月
A1: 6月度 工数明細 | C1: =IF(AND(サマリ!$B$2=YEAR(TODAY()),MONTH(TODAY())=6),"★ 当月","") | E1: 月合計 | F1: =SUM(F4:F503) -> 0
A2: ※4行目〜503行目に明細を貼り付けてください（合計行はその下）。日付はYYYYMM形式（例：202601）。
A3: 日付 | B3: 行程 | C3: タスク1 | D3: タスク2 | E3: タスク3 | F3: 工数 | G3: 担当者 | H3: 備考
E505: 合計 | F505: =SUM(F4:F503) -> 0

Sheet 07月
A1: 7月度 工数明細 | C1: =IF(AND(サマリ!$B$2=YEAR(TODAY()),MONTH(TODAY())=7),"★ 当月","") | E1: 月合計 | F1: =SUM(F4:F503) -> 0
A2: ※4行目〜503行目に明細を貼り付けてください（合計行はその下）。日付はYYYYMM形式（例：202601）。
A3: 日付 | B3: 行程 | C3: タスク1 | D3: タスク2 | E3: タスク3 | F3: 工数 | G3: 担当者 | H3: 備考
E505: 合計 | F505: =SUM(F4:F503) -> 0

Sheet 08月
A1: 8月度 工数明細 | C1: =IF(AND(サマリ!$B$2=YEAR(TODAY()),MONTH(TODAY())=8),"★ 当月","") -> ★ 当月 | E1: 月合計 | F1: =SUM(F4:F503) -> 0
A2: ※4行目〜503行目に明細を貼り付けてください（合計行はその下）。日付はYYYYMM形式（例：202601）。
A3: 日付 | B3: 行程 | C3: タスク1 | D3: タスク2 | E3: タスク3 | F3: 工数 | G3: 担当者 | H3: 備考
E505: 合計 | F505: =SUM(F4:F503) -> 0

Sheet 09月
A1: 9月度 工数明細 | C1: =IF(AND(サマリ!$B$2=YEAR(TODAY()),MONTH(TODAY())=9),"★ 当月","") | E1: 月合計 | F1: =SUM(F4:F503) -> 0
A2: ※4行目〜503行目に明細を貼り付けてください（合計行はその下）。日付はYYYYMM形式（例：202601）。
A3: 日付 | B3: 行程 | C3: タスク1 | D3: タスク2 | E3: タスク3 | F3: 工数 | G3: 担当者 | H3: 備考
E505: 合計 | F505: =SUM(F4:F503) -> 0

Sheet 10月
A1: 10月度 工数明細 | C1: =IF(AND(サマリ!$B$2=YEAR(TODAY()),MONTH(TODAY())=10),"★ 当月","") | E1: 月合計 | F1: =SUM(F4:F503) -> 0
A2: ※4行目〜503行目に明細を貼り付けてください（合計行はその下）。日付はYYYYMM形式（例：202601）。
A3: 日付 | B3: 行程 | C3: タスク1 | D3: タスク2 | E3: タスク3 | F3: 工数 | G3: 担当者 | H3: 備考
E505: 合計 | F505: =SUM(F4:F503) -> 0

Sheet 11月
A1: 11月度 工数明細 | C1: =IF(AND(サマリ!$B$2=YEAR(TODAY()),MONTH(TODAY())=11),"★ 当月","") | E1: 月合計 | F1: =SUM(F4:F503) -> 0
A2: ※4行目〜503行目に明細を貼り付けてください（合計行はその下）。日付はYYYYMM形式（例：202601）。
A3: 日付 | B3: 行程 | C3: タスク1 | D3: タスク2 | E3: タスク3 | F3: 工数 | G3: 担当者 | H3: 備考
E505: 合計 | F505: =SUM(F4:F503) -> 0

Sheet 12月
A1: 12月度 工数明細 | C1: =IF(AND(サマリ!$B$2=YEAR(TODAY()),MONTH(TODAY())=12),"★ 当月","") | E1: 月合計 | F1: =SUM(F4:F503) -> 0
A2: ※4行目〜503行目に明細を貼り付けてください（合計行はその下）。日付はYYYYMM形式（例：202601）。
A3: 日付 | B3: 行程 | C3: タスク1 | D3: タスク2 | E3: タスク3 | F3: 工数 | G3: 担当者 | H3: 備考
E505: 合計 | F505: =SUM(F4:F503) -> 0

Sheet 数式
A1: 貼り付け用の数式
A2: 各集計シートの水色セルに、下の数式をそのままコピー＆ペーストしてください。必ず A5 → B5 → N5 → O5 → B3 → N3 の順で貼ってください。
A3: ※Microsoft 365 / Excel 2021 以降が必要です（UNIQUE・SORT・FILTER・スピル対応のSUMIFS）。
A5: ■ 集計_行程
A6: 貼り付け先 | B6: 内容 | C6: 数式
A7: A5 | B7: 項目一覧（重複なし・自動展開） | C7: {=_xlfn._xlws.SORT(_xlfn.UNIQUE(_xlfn._xlws.FILTER(統合データ!$B$2:$B$6001,統合データ!$B$2:$B$6001<>"")))} -> 一次保守
A8: B5 | B8: 1月〜12月の工数（12列に自動展開） | C8: =SUMIFS(統合データ!$F$2:$F$6001,統合データ!$B$2:$B$6001,$A5#,統合データ!$A$2:$A$6001,B$4:M$4)
A9: N5 | B9: 行合計 | C9: =SUMIFS(統合データ!$F$2:$F$6001,統合データ!$B$2:$B$6001,$A5#)
A10: O5 | B10: 構成比 | C10: =IFERROR(N5#/$N$3,"")
A11: B3 | B11: 月別合計（12列に自動展開） | C11: =SUMIFS(統合データ!$F$2:$F$6001,統合データ!$A$2:$A$6001,B4:M4)
A12: N3 | B12: 総合計 | C12: =SUM(統合データ!$F$2:$F$6001)
A14: ■ 集計_タスク1
A15: 貼り付け先 | B15: 内容 | C15: 数式
A16: A5 | B16: 項目一覧（重複なし・自動展開） | C16: =SORT(UNIQUE(FILTER(統合データ!$C$2:$C$6001,統合データ!$C$2:$C$6001<>"")))
A17: B5 | B17: 1月〜12月の工数（12列に自動展開） | C17: =SUMIFS(統合データ!$F$2:$F$6001,統合データ!$C$2:$C$6001,$A5#,統合データ!$A$2:$A$6001,B$4:M$4)
A18: N5 | B18: 行合計 | C18: =SUMIFS(統合データ!$F$2:$F$6001,統合データ!$C$2:$C$6001,$A5#)
A19: O5 | B19: 構成比 | C19: =IFERROR(N5#/$N$3,"")
A20: B3 | B20: 月別合計（12列に自動展開） | C20: =SUMIFS(統合データ!$F$2:$F$6001,統合データ!$A$2:$A$6001,B4:M4)
A21: N3 | B21: 総合計 | C21: =SUM(統合データ!$F$2:$F$6001)
A23: ■ 集計_タスク2
A24: 貼り付け先 | B24: 内容 | C24: 数式
A25: A5 | B25: 項目一覧（重複なし・自動展開） | C25: =SORT(UNIQUE(FILTER(統合データ!$D$2:$D$6001,統合データ!$D$2:$D$6001<>"")))
A26: B5 | B26: 1月〜12月の工数（12列に自動展開） | C26: =SUMIFS(統合データ!$F$2:$F$6001,統合データ!$D$2:$D$6001,$A5#,統合データ!$A$2:$A$6001,B$4:M$4)
A27: N5 | B27: 行合計 | C27: =SUMIFS(統合データ!$F$2:$F$6001,統合データ!$D$2:$D$6001,$A5#)
A28: O5 | B28: 構成比 | C28: =IFERROR(N5#/$N$3,"")
A29: B3 | B29: 月別合計（12列に自動展開） | C29: =SUMIFS(統合データ!$F$2:$F$6001,統合データ!$A$2:$A$6001,B4:M4)
A30: N3 | B30: 総合計 | C30: =SUM(統合データ!$F$2:$F$6001)
A32: ■ 集計_担当者
A33: 貼り付け先 | B33: 内容 | C33: 数式
A34: A5 | B34: 項目一覧（重複なし・自動展開） | C34: =SORT(UNIQUE(FILTER(統合データ!$E$2:$E$6001,統合データ!$E$2:$E$6001<>"")))
A35: B5 | B35: 1月〜12月の工数（12列に自動展開） | C35: =SUMIFS(統合データ!$F$2:$F$6001,統合データ!$E$2:$E$6001,$A5#,統合データ!$A$2:$A$6001,B$4:M$4)
A36: N5 | B36: 行合計 | C36: =SUMIFS(統合データ!$F$2:$F$6001,統合データ!$E$2:$E$6001,$A5#)
A37: O5 | B37: 構成比 | C37: =IFERROR(N5#/$N$3,"")
A38: B3 | B38: 月別合計（12列に自動展開） | C38: =SUMIFS(統合データ!$F$2:$F$6001,統合データ!$A$2:$A$6001,B4:M4)
A39: N3 | B39: 総合計 | C39: =SUM(統合データ!$F$2:$F$6001)
A41: 【コツ】集計_行程 に6本貼り終えたら、A3:O5 をコピーして他の3シートの同じ位置に貼り、
A42: そのシート内で「検索と置換」を使い、$B$2:$B$6001 を $C$2:$C$6001（タスク1）などに置き換える方が早いです。
A43: 対応：行程=B列 / タスク1=C列 / タスク2=D列 / 担当者=E列（統合データシートの列）

Sheet 使い方
A1: 年間工数管理ファイル 使い方
A3: 【最初に1度だけ行う設定】
A4: 「数式」シートを開き、4つの集計シート（集計_行程／集計_タスク1／集計_タスク2／集計_担当者）の水色セルに数式を貼り付けます。
A5: 貼り付け順は A5 → B5 → N5 → O5 → B3 → N3 です（A5の結果を他の数式が参照するため）。
A6: 1シート貼り終えたら A3:O5 をコピーして他シートに貼り、「検索と置換」で参照列を変える方法が早いです（詳細は数式シート下部）。
A7: ※Microsoft 365 / Excel 2021 以降が必要です。それ以前のバージョンではスピルが動作しません。
A9: 【毎月の作業】
A10: 1. 社内システムから当月の工数明細を出力する。
A11: 2. 該当月シートのA4セルを選び、「値のみ貼り付け」で明細を貼り付ける。
A12: 列の順序：日付／行程／タスク1／タスク2／タスク3／工数／担当者／備考
A13: 日付はYYYYMM形式（例：202601）で入力してください。
A14: 3. 以上で完了です。集計シートの項目・行数・グラフはすべて自動更新されます。
... A46: このファイルをコピーし、各月シートの4〜503行目を削除、サマリB2の年を変更すれば再利用できます。

Sheet 統合データ
A1: 月 | B1: 行程 | C1: タスク1 | D1: タスク2 | E1: 担当者 | F1: 工数 | H1: ※このシートは各月シートを縦に連結した集計用の作業データです。編集しないでください。
A2: 1 | B2: =IF('01月'!B4="","",'01月'!B4) -> 一次保守 | C2: =IF('01月'!C4="","",'01月'!C4) -> 問い合わせ対応 | D2: =IF('01月'!D4="","",'01月'!D4) -> ●●社問い合わせ対応 | E2: =IF('01月'!G4="","",'01月'!G4) -> 山田 | F2: =IF('01月'!F4="",0,'01月'!F4) -> 3.5
A3: 1 | B3: =IF('01月'!B5="","",'01月'!B5) | C3: =IF('01月'!C5="","",'01月'!C5) | D3: =IF('01月'!D5="","",'01月'!D5) | E3: =IF('01月'!G5="","",'01月'!G5) | F3: =IF('01月'!F5="",0,'01月'!F5) -> 0
A4: 1 | B4: =IF('01月'!B6="","",'01月'!B6) | C4: =IF('01月'!C6="","",'01月'!C6) | D4: =IF('01月'!D6="","",'01月'!D6) | E4: =IF('01月'!G6="","",'01月'!G6) | F4: =IF('01月'!F6="",0,'01月'!F6) -> 0
A5: 1 | B5: =IF('01月'!B7="","",'01月'!B7) | C5: =IF('01月'!C7="","",'01月'!C7) | D5: =IF('01月'!D7="","",'01月'!D7) | E5: =IF('01月'!G7="","",'01月'!G7) | F5: =IF('01月'!F7="",0,'01月'!F7) -> 0
A6: 1 | B6: =IF('01月'!B8="","",'01月'!B8) | C6: =IF('01月'!C8="","",'01月'!C8) | D6: =IF('01月'!D8="","",'01月'!D8) | E6: =IF('01月'!G8="","",'01月'!G8) | F6: =IF('01月'!F8="",0,'01月'!F8) -> 0
A7: 1 | B7: =IF('01月'!B9="","",'01月'!B9) | C7: =IF('01月'!C9="","",'01月'!C9) | D7: =IF('01月'!D9="","",'01月'!D9) | E7: =IF('01月'!G9="","",'01月'!G9) | F7: =IF('01月'!F9="",0,'01月'!F9) -> 0
A8: 1 | B8: =IF('01月'!B10="","",'01月'!B10) | C8: =IF('01月'!C10="","",'01月'!C10) | D8: =IF('01月'!D10="","",'01月'!D10) | E8: =IF('01月'!G10="","",'01月'!G10) | F8: =IF('01月'!F10="",0,'01月'!F10) -> 0
A9: 1 | B9: =IF('01月'!B11="","",'01月'!B11) | C9: =IF('01月'!C11="","",'01月'!C11) | D9: =IF('01月'!D11="","",'01月'!D11) | E9: =IF('01月'!G11="","",'01月'!G11) | F9: =IF('01月'!F11="",0,'01月'!F11) -> 0
A10: 1 | B10: =IF('01月'!B12="","",'01月'!B12) | C10: =IF('01月'!C12="","",'01月'!C12) | D10: =IF('01月'!D12="","",'01月'!D12) | E10: =IF('01月'!G12="","",'01月'!G12) | F10: =IF('01月'!F12="",0,'01月'!F12) -> 0
A11: 1 | B11: =IF('01月'!B13="","",'01月'!B13) | C11: =IF('01月'!C13="","",'01月'!C13) | D11: =IF('01月'!D13="","",'01月'!D13) | E11: =IF('01月'!G13="","",'01月'!G13) | F11: =IF('01月'!F13="",0,'01月'!F13) -> 0
A12: 1 | B12: =IF('01月'!B14="","",'01月'!B14) | C12: =IF('01月'!C14="","",'01月'!C14) | D12: =IF('01月'!D14="","",'01月'!D14) | E12: =IF('01月'!G14="","",'01月'!G14) | F12: =IF('01月'!F14="",0,'01月'!F14) -> 0
A13: 1 | B13: =IF('01月'!B15="","",'01月'!B15) | C13: =IF('01月'!C15="","",'01月'!C15) | D13: =IF('01月'!D15="","",'01月'!D15) | E13: =IF('01月'!G15="","",'01月'!G15) | F13: =IF('01月'!F15="",0,'01月'!F15) -> 0
... A501: 1 | B501: =IF('01月'!B503="","",'01月'!B503) | C501: =IF('01月'!C503="","",'01月'!C503) | D501: =IF('01月'!D503="","",'01月'!D503) | E501: =IF('01月'!G503="","",'01月'!G503) | F501: =IF('01月'!F503="",0,'01月'!F503) -> 0
A502: 2 | B502: =IF('02月'!B4="","",'02月'!B4) | C502: =IF('02月'!C4="","",'02月'!C4) | D502: =IF('02月'!D4="","",'02月'!D4) | E502: =IF('02月'!G4="","",'02月'!G4) | F502: =IF('02月'!F4="",0,'02月'!F4) -> 0
A503: 2 | B503: =IF('02月'!B5="","",'02月'!B5) | C503: =IF('02月'!C5="","",'02月'!C5) | D503: =IF('02月'!D5="","",'02月'!D5) | E503: =IF('02月'!G5="","",'02月'!G5) | F503: =IF('02月'!F5="",0,'02月'!F5) -> 0
A504: 2 | B504: =IF('02月'!B6="","",'02月'!B6) | C504: =IF('02月'!C6="","",'02月'!C6) | D504: =IF('02月'!D6="","",'02月'!D6) | E504: =IF('02月'!G6="","",'02月'!G6) | F504: =IF('02月'!F6="",0,'02月'!F6) -> 0
A505: 2 | B505: =IF('02月'!B7="","",'02月'!B7) | C505: =IF('02月'!C7="","",'02月'!C7) | D505: =IF('02月'!D7="","",'02月'!D7) | E505: =IF('02月'!G7="","",'02月'!G7) | F505: =IF('02月'!F7="",0,'02月'!F7) -> 0
A506: 2 | B506: =IF('02月'!B8="","",'02月'!B8) | C506: =IF('02月'!C8="","",'02月'!C8) | D506: =IF('02月'!D8="","",'02月'!D8) | E506: =IF('02月'!G8="","",'02月'!G8) | F506: =IF('02月'!F8="",0,'02月'!F8) -> 0
A507: 2 | B507: =IF('02月'!B9="","",'02月'!B9) | C507: =IF('02月'!C9="","",'02月'!C9) | D507: =IF('02月'!D9="","",'02月'!D9) | E507: =IF('02月'!G9="","",'02月'!G9) | F507: =IF('02月'!F9="",0,'02月'!F9) -> 0
A508: 2 | B508: =IF('02月'!B10="","",'02月'!B10) | C508: =IF('02月'!C10="","",'02月'!C10) | D508: =IF('02月'!D10="","",'02月'!D10) | E508: =IF('02月'!G10="","",'02月'!G10) | F508: =IF('02月'!F10="",0,'02月'!F10) -> 0
A509: 2 | B509: =IF('02月'!B11="","",'02月'!B11) | C509: =IF('02月'!C11="","",'02月'!C11) | D509: =IF('02月'!D11="","",'02月'!D11) | E509: =IF('02月'!G11="","",'02月'!G11) | F509: =IF('02月'!F11="",0,'02月'!F11) -> 0
A510: 2 | B510: =IF('02月'!B12="","",'02月'!B12) | C510: =IF('02月'!C12="","",'02月'!C12) | D510: =IF('02月'!D12="","",'02月'!D12) | E510: =IF('02月'!G12="","",'02月'!G12) | F510: =IF('02月'!F12="",0,'02月'!F12) -> 0
A511: 2 | B511: =IF('02月'!B13="","",'02月'!B13) | C511: =IF('02月'!C13="","",'02月'!C13) | D511: =IF('02月'!D13="","",'02月'!D13) | E511: =IF('02月'!G13="","",'02月'!G13) | F511: =IF('02月'!F13="",0,'02月'!F13) -> 0
A512: 2 | B512: =IF('02月'!B14="","",'02月'!B14) | C512: =IF('02月'!C14="","",'02月'!C14) | D512: =IF('02月'!D14="","",'02月'!D14) | E512: =IF('02月'!G14="","",'02月'!G14) | F512: =IF('02月'!F14="",0,'02月'!F14) -> 0
A513: 2 | B513: =IF('02月'!B15="","",'02月'!B15) | C513: =IF('02月'!C15="","",'02月'!C15) | D513: =IF('02月'!D15="","",'02月'!D15) | E513: =IF('02月'!G15="","",'02月'!G15) | F513: =IF('02月'!F15="",0,'02月'!F15) -> 0
... A1001: 2 | B1001: =IF('02月'!B503="","",'02月'!B503) | C1001: =IF('02月'!C503="","",'02月'!C503) | D1001: =IF('02月'!D503="","",'02月'!D503) | E1001: =IF('02月'!G503="","",'02月'!G503) | F1001: =IF('02月'!F503="",0,'02月'!F503) -> 0
A1002: 3 | B1002: =IF('03月'!B4="","",'03月'!B4) | C1002: =IF('03月'!C4="","",'03月'!C4) | D1002: =IF('03月'!D4="","",'03月'!D4) | E1002: =IF('03月'!G4="","",'03月'!G4) | F1002: =IF('03月'!F4="",0,'03月'!F4) -> 0
A1003: 3 | B1003: =IF('03月'!B5="","",'03月'!B5) | C1003: =IF('03月'!C5="","",'03月'!C5) | D1003: =IF('03月'!D5="","",'03月'!D5) | E1003: =IF('03月'!G5="","",'03月'!G5) | F1003: =IF('03月'!F5="",0,'03月'!F5) -> 0
A1004: 3 | B1004: =IF('03月'!B6="","",'03月'!B6) | C1004: =IF('03月'!C6="","",'03月'!C6) | D1004: =IF('03月'!D6="","",'03月'!D6) | E1004: =IF('03月'!G6="","",'03月'!G6) | F1004: =IF('03月'!F6="",0,'03月'!F6) -> 0
A1005: 3 | B1005: =IF('03月'!B7="","",'03月'!B7) | C1005: =IF('03月'!C7="","",'03月'!C7) | D1005: =IF('03月'!D7="","",'03月'!D7) | E1005: =IF('03月'!G7="","",'03月'!G7) | F1005: =IF('03月'!F7="",0,'03月'!F7) -> 0
A1006: 3 | B1006: =IF('03月'!B8="","",'03月'!B8) | C1006: =IF('03月'!C8="","",'03月'!C8) | D1006: =IF('03月'!D8="","",'03月'!D8) | E1006: =IF('03月'!G8="","",'03月'!G8) | F1006: =IF('03月'!F8="",0,'03月'!F8) -> 0
A1007: 3 | B1007: =IF('03月'!B9="","",'03月'!B9) | C1007: =IF('03月'!C9="","",'03月'!C9) | D1007: =IF('03月'!D9="","",'03月'!D9) | E1007: =IF('03月'!G9="","",'03月'!G9) | F1007: =IF('03月'!F9="",0,'03月'!F9) -> 0
A1008: 3 | B1008: =IF('03月'!B10="","",'03月'!B10) | C1008: =IF('03月'!C10="","",'03月'!C10) | D1008: =IF('03月'!D10="","",'03月'!D10) | E1008: =IF('03月'!G10="","",'03月'!G10) | F1008: =IF('03月'!F10="",0,'03月'!F10) -> 0
A1009: 3 | B1009: =IF('03月'!B11="","",'03月'!B11) | C1009: =IF('03月'!C11="","",'03月'!C11) | D1009: =IF('03月'!D11="","",'03月'!D11) | E1009: =IF('03月'!G11="","",'03月'!G11) | F1009: =IF('03月'!F11="",0,'03月'!F11) -> 0
A1010: 3 | B1010: =IF('03月'!B12="","",'03月'!B12) | C1010: =IF('03月'!C12="","",'03月'!C12) | D1010: =IF('03月'!D12="","",'03月'!D12) | E1010: =IF('03月'!G12="","",'03月'!G12) | F1010: =IF('03月'!F12="",0,'03月'!F12) -> 0
A1011: 3 | B1011: =IF('03月'!B13="","",'03月'!B13) | C1011: =IF('03月'!C13="","",'03月'!C13) | D1011: =IF('03月'!D13="","",'03月'!D13) | E1011: =IF('03月'!G13="","",'03月'!G13) | F1011: =IF('03月'!F13="",0,'03月'!F13) -> 0
A1012: 3 | B1012: =IF('03月'!B14="","",'03月'!B14) | C1012: =IF('03月'!C14="","",'03月'!C14) | D1012: =IF('03月'!D14="","",'03月'!D14) | E1012: =IF('03月'!G14="","",'03月'!G14) | F1012: =IF('03月'!F14="",0,'03月'!F14) -> 0
A1013: 3 | B1013: =IF('03月'!B15="","",'03月'!B15) | C1013: =IF('03月'!C15="","",'03月'!C15) | D1013: =IF('03月'!D15="","",'03月'!D15) | E1013: =IF('03月'!G15="","",'03月'!G15) | F1013: =IF('03月'!F15="",0,'03月'!F15) -> 0
... A1501: 3 | B1501: =IF('03月'!B503="","",'03月'!B503) | C1501: =IF('03月'!C503="","",'03月'!C503) | D1501: =IF('03月'!D503="","",'03月'!D503) | E1501: =IF('03月'!G503="","",'03月'!G503) | F1501: =IF('03月'!F503="",0,'03月'!F503) -> 0
...
